<?xml version="1.0" ?>
<!-- =================================================================================== -->
<!-- |    This document was autogenerated by xacro from so101.urdf.xacro               | -->
<!-- |    EDITING THIS FILE BY HAND IS NOT RECOMMENDED                                 | -->
<!-- =================================================================================== -->
<robot name="so101">
  <!-- Shared constants/properties (no includes here) -->
  <!-- <xacro:property name="mesh_dir" value="$(find so101_description)/meshes/assets"/> -->
  <!-- <xacro:property name="mesh_dir" value="package://so101_description/meshes/so101"/> -->
  <!-- STL filenames (as used by your original file) -->
  <!-- <xacro:property name="stl_base_holder"           value="base_motor_holder_so101_v1.stl"/>
  <xacro:property name="stl_base"                  value="base_so101_v2.stl"/>
  <xacro:property name="stl_servo"                 value="sts3215_03a_v1.stl"/>
  <xacro:property name="stl_servo_nohorn"          value="sts3215_03a_no_horn_v1.stl"/>
  <xacro:property name="stl_waveshare"             value="waveshare_mounting_plate_so101_v2.stl"/>
  <xacro:property name="stl_rotation_pitch"        value="rotation_pitch_so101_v1.stl"/>
  <xacro:property name="stl_upper_arm"             value="upper_arm_so101_v1.stl"/>
  <xacro:property name="stl_under_arm"             value="under_arm_so101_v1.stl"/>
  <xacro:property name="stl_wrist_holder"          value="motor_holder_so101_wrist_v1.stl"/>
  <xacro:property name="stl_wrist_roll_pitch"      value="wrist_roll_pitch_so101_v2.stl"/>
  <xacro:property name="stl_wrist_roll_follower"   value="wrist_roll_follower_so101_v1.stl"/>
  <xacro:property name="stl_moving_jaw"            value="moving_jaw_so101_v1.stl"/>
  <xacro:property name="stl_motor_holder_base"     value="motor_holder_so101_base_v1.stl"/> -->
  <material name="3d_printed">
    <color rgba="1.0 0.82 0.12 1.0"/>
  </material>
  <material name="sts3215">
    <color rgba="0.1 0.1 0.1 1.0"/>
  </material>
  <link name="world"/>
  <!-- Link base -->
  <link name="base_link">
    <inertial>
      <origin rpy="0 0 0" xyz="0.0137179 -5.19711e-05 0.0334843"/>
      <mass value="0.147"/>
      <inertia ixx="0.000114686" ixy="-4.59787e-07" ixz="4.97151e-06" iyy="0.000136117" iyz="9.75275e-08" izz="0.000130364"/>
    </inertial>
    <!-- Part base_motor_holder_so101_v1 -->
    <visual>
      <origin rpy="1.5708 -1.67685e-15 1.5708" xyz="-0.00636471 -9.94414e-05 -0.0024"/>
      <geometry>
        <mesh filename="package://so101_description/meshes/so101/base_motor_holder_so101_v1.stl"/>
      </geometry>
      <material name="3d_printed"/>
    </visual>
    <collision>
      <origin rpy="1.5708 -1.67685e-15 1.5708" xyz="-0.00636471 -9.94414e-05 -0.0024"/>
      <geometry>
        <mesh filename="package://so101_description/meshes/so101/base_motor_holder_so101_v1.stl"/>
      </geometry>
    </collision>
    <!-- Part base_so101_v2 -->
    <visual>
      <origin rpy="1.5708 -2.78073e-29 1.5708" xyz="-0.00636471 -8.97657e-09 -0.0024"/>
      <geometry>
        <mesh filename="package://so101_description/meshes/so101/base_so101_v2.stl"/>
      </geometry>
      <material name="3d_printed"/>
    </visual>
    <collision>
      <origin rpy="1.5708 -2.78073e-29 1.5708" xyz="-0.00636471 -8.97657e-09 -0.0024"/>
      <geometry>
        <mesh filename="package://so101_description/meshes/so101/base_so101_v2.stl"/>
      </geometry>
    </collision>
    <!-- Part sts3215_03a_v1 -->
    <visual>
      <origin rpy="-8.21148e-16 7.84513e-18 1.249e-15" xyz="0.0263353 -8.97657e-09 0.0437"/>
      <geometry>
        <mesh filename="package://so101_description/meshes/so101/sts3215_03a_v1.stl"/>
      </geometry>
      <material name="sts3215"/>
    </visual>
    <collision>
      <origin rpy="-8.21148e-16 7.84513e-18 1.249e-15" xyz="0.0263353 -8.97657e-09 0.0437"/>
      <geometry>
        <mesh filename="package://so101_description/meshes/so101/sts3215_03a_v1.stl"/>
      </geometry>
    </collision>
    <!-- Part waveshare_mounting_plate_so101_v2 -->
    <visual>
      <origin rpy="1.5708 -1.35493e-14 1.5708" xyz="-0.0309827 -0.000199441 0.0474"/>
      <geometry>
        <mesh filename="package://so101_description/meshes/so101/waveshare_mounting_plate_so101_v2.stl"/>
      </geometry>
      <material name="3d_printed"/>
    </visual>
    <collision>
      <origin rpy="1.5708 -1.35493e-14 1.5708" xyz="-0.0309827 -0.000199441 0.0474"/>
      <geometry>
        <mesh filename="package://so101_description/meshes/so101/waveshare_mounting_plate_so101_v2.stl"/>
      </geometry>
    </collision>
  </link>
  <!-- Link shoulder -->
  <link name="shoulder_link">
    <inertial>
      <origin rpy="0 0 0" xyz="-0.0307604 -1.66727e-05 -0.0252713"/>
      <mass value="0.100006"/>
      <inertia ixx="8.3759e-05" ixy="7.55525e-08" ixz="-1.16342e-06" iyy="8.10403e-05" iyz="1.54663e-07" izz="2.39783e-05"/>
    </inertial>
    <!-- Part sts3215_03a_v1_2 -->
    <visual>
      <origin rpy="1.5708 1.5708 0" xyz="-0.0303992 0.000422241 -0.0417"/>
      <geometry>
        <mesh filename="package://so101_description/meshes/so101/sts3215_03a_v1.stl"/>
      </geometry>
      <material name="sts3215"/>
    </visual>
    <collision>
      <origin rpy="1.5708 1.5708 0" xyz="-0.0303992 0.000422241 -0.0417"/>
      <geometry>
        <mesh filename="package://so101_description/meshes/so101/sts3215_03a_v1.stl"/>
      </geometry>
    </collision>
    <!-- Part motor_holder_so101_base_v1 -->
    <visual>
      <origin rpy="1.5708 -1.5708 0" xyz="-0.0675992 -0.000177759 0.0158499"/>
      <geometry>
        <mesh filename="package://so101_description/meshes/so101/motor_holder_so101_base_v1.stl"/>
      </geometry>
      <material name="3d_printed"/>
    </visual>
    <collision>
      <origin rpy="1.5708 -1.5708 0" xyz="-0.0675992 -0.000177759 0.0158499"/>
      <geometry>
        <mesh filename="package://so101_description/meshes/so101/motor_holder_so101_base_v1.stl"/>
      </geometry>
    </collision>
    <!-- Part rotation_pitch_so101_v1 -->
    <visual>
      <origin rpy="-1.5708 2.35221e-33 0" xyz="0.0122008 2.22413e-05 0.0464"/>
      <geometry>
        <mesh filename="package://so101_description/meshes/so101/rotation_pitch_so101_v1.stl"/>
      </geometry>
      <material name="3d_printed"/>
    </visual>
    <collision>
      <origin rpy="-1.5708 2.35221e-33 0" xyz="0.0122008 2.22413e-05 0.0464"/>
      <geometry>
        <mesh filename="package://so101_description/meshes/so101/rotation_pitch_so101_v1.stl"/>
      </geometry>
    </collision>
  </link>
  <!-- Link upper_arm -->
  <link name="upper_arm_link">
    <inertial>
      <origin rpy="0 0 0" xyz="-0.0898471 -0.00838224 0.0184089"/>
      <mass value="0.103"/>
      <inertia ixx="4.08002e-05" ixy="-1.97819e-05" ixz="-4.03016e-08" iyy="0.000147318" iyz="8.97326e-09" izz="0.000142487"/>
    </inertial>
    <!-- Part sts3215_03a_v1_3 -->
    <visual>
      <origin rpy="-3.14159 -5.27356e-16 -1.5708" xyz="-0.11257 -0.0155 0.0187"/>
      <geometry>
        <mesh filename="package://so101_description/meshes/so101/sts3215_03a_v1.stl"/>
      </geometry>
      <material name="sts3215"/>
    </visual>
    <collision>
      <origin rpy="-3.14159 -5.27356e-16 -1.5708" xyz="-0.11257 -0.0155 0.0187"/>
      <geometry>
        <mesh filename="package://so101_description/meshes/so101/sts3215_03a_v1.stl"/>
      </geometry>
    </collision>
    <!-- Part upper_arm_so101_v1 -->
    <visual>
      <origin rpy="3.14159 -0 -1.30911e-30" xyz="-0.065085 0.012 0.0182"/>
      <geometry>
        <mesh filename="package://so101_description/meshes/so101/upper_arm_so101_v1.stl"/>
      </geometry>
      <material name="3d_printed"/>
    </visual>
    <collision>
      <origin rpy="3.14159 -0 -1.30911e-30" xyz="-0.065085 0.012 0.0182"/>
      <geometry>
        <mesh filename="package://so101_description/meshes/so101/upper_arm_so101_v1.stl"/>
      </geometry>
    </collision>
  </link>
  <!-- Link lower_arm -->
  <link name="lower_arm_link">
    <inertial>
      <origin rpy="0 0 0" xyz="-0.0980701 0.00324376 0.0182831"/>
      <mass value="0.104"/>
      <inertia ixx="2.87438e-05" ixy="7.41152e-06" ixz="1.26409e-06" iyy="0.000159844" iyz="-4.90188e-08" izz="0.00014529"/>
    </inertial>
    <!-- Part under_arm_so101_v1 -->
    <visual>
      <origin rpy="3.14159 -0 6.67202e-31" xyz="-0.0648499 -0.032 0.0182"/>
      <geometry>
        <mesh filename="package://so101_description/meshes/so101/under_arm_so101_v1.stl"/>
      </geometry>
      <material name="3d_printed"/>
    </visual>
    <collision>
      <origin rpy="3.14159 -0 6.67202e-31" xyz="-0.0648499 -0.032 0.0182"/>
      <geometry>
        <mesh filename="package://so101_description/meshes/so101/under_arm_so101_v1.stl"/>
      </geometry>
    </collision>
    <!-- Part motor_holder_so101_wrist_v1 -->
    <visual>
      <origin rpy="-3.14159 -2.55351e-15 -1.83387e-30" xyz="-0.0648499 -0.032 0.018"/>
      <geometry>
        <mesh filename="package://so101_description/meshes/so101/motor_holder_so101_wrist_v1.stl"/>
      </geometry>
      <material name="3d_printed"/>
    </visual>
    <collision>
      <origin rpy="-3.14159 -2.55351e-15 -1.83387e-30" xyz="-0.0648499 -0.032 0.018"/>
      <geometry>
        <mesh filename="package://so101_description/meshes/so101/motor_holder_so101_wrist_v1.stl"/>
      </geometry>
    </collision>
    <!-- Part sts3215_03a_v1_4 -->
    <visual>
      <origin rpy="-3.14159 -7.88861e-31 -3.14159" xyz="-0.1224 0.0052 0.0187"/>
      <geometry>
        <mesh filename="package://so101_description/meshes/so101/sts3215_03a_v1.stl"/>
      </geometry>
      <material name="sts3215"/>
    </visual>
    <collision>
      <origin rpy="-3.14159 -7.88861e-31 -3.14159" xyz="-0.1224 0.0052 0.0187"/>
      <geometry>
        <mesh filename="package://so101_description/meshes/so101/sts3215_03a_v1.stl"/>
      </geometry>
    </collision>
  </link>
  <!-- Link wrist -->
  <link name="wrist_link">
    <inertial>
      <origin rpy="0 0 0" xyz="-0.000103312 -0.0386143 0.0281156"/>
      <mass value="0.079"/>
      <inertia ixx="3.68263e-05" ixy="1.7893e-08" ixz="-5.28128e-08" iyy="2.5391e-05" iyz="3.6412e-06" izz="2.1e-05"/>
    </inertial>
    <!-- Part sts3215_03a_no_horn_v1 -->
    <visual>
      <origin rpy="1.5708 1.5708 0" xyz="8.32667e-17 -0.0424 0.0306"/>
      <geometry>
        <mesh filename="package://so101_description/meshes/so101/sts3215_03a_no_horn_v1.stl"/>
      </geometry>
      <material name="sts3215"/>
    </visual>
    <collision>
      <origin rpy="1.5708 1.5708 0" xyz="8.32667e-17 -0.0424 0.0306"/>
      <geometry>
        <mesh filename="package://so101_description/meshes/so101/sts3215_03a_no_horn_v1.stl"/>
      </geometry>
    </collision>
    <!-- Part wrist_roll_pitch_so101_v2 -->
    <visual>
      <origin rpy="-1.5708 -1.5708 0" xyz="0 -0.028 0.0181"/>
      <geometry>
        <mesh filename="package://so101_description/meshes/so101/wrist_roll_pitch_so101_v2.stl"/>
      </geometry>
      <material name="3d_printed"/>
    </visual>
    <collision>
      <origin rpy="-1.5708 -1.5708 0" xyz="0 -0.028 0.0181"/>
      <geometry>
        <mesh filename="package://so101_description/meshes/so101/wrist_roll_pitch_so101_v2.stl"/>
      </geometry>
    </collision>
  </link>
  <!-- Link gripper -->
  <link name="gripper_link">
    <inertial>
      <origin rpy="0 0 0" xyz="0.000213627 0.000245138 -0.025187"/>
      <mass value="0.087"/>
      <inertia ixx="2.75087e-05" ixy="-3.35241e-07" ixz="-5.7352e-06" iyy="4.33657e-05" iyz="-5.17847e-08" izz="3.45059e-05"/>
    </inertial>
    <!-- Part sts3215_03a_v1_5 -->
    <visual>
      <origin rpy="-1.5708 -5.19179e-17 -1.66533e-16" xyz="0.0077 0.0001 -0.0234"/>
      <geometry>
        <mesh filename="package://so101_description/meshes/so101/sts3215_03a_v1.stl"/>
      </geometry>
      <material name="sts3215"/>
    </visual>
    <collision>
      <origin rpy="-1.5708 -5.19179e-17 -1.66533e-16" xyz="0.0077 0.0001 -0.0234"/>
      <geometry>
        <mesh filename="package://so101_description/meshes/so101/sts3215_03a_v1.stl"/>
      </geometry>
    </collision>
    <!-- Part wrist_roll_follower_so101_v1 -->
    <visual>
      <origin rpy="-3.14159 -5.55112e-17 0" xyz="8.32667e-17 -0.000218214 0.000949706"/>
      <geometry>
        <mesh filename="package://so101_description/meshes/so101/wrist_roll_follower_so101_v1.stl"/>
      </geometry>
      <material name="3d_printed"/>
    </visual>
    <collision>
      <origin rpy="-3.14159 -5.55112e-17 0" xyz="8.32667e-17 -0.000218214 0.000949706"/>
      <geometry>
        <mesh filename="package://so101_description/meshes/so101/wrist_roll_follower_so101_v1.stl"/>
      </geometry>
    </collision>
  </link>
  <!-- Gripper frame (dummy link + fixed joint) -->
  <link name="gripper_frame_link">
    <origin rpy="0 -0 0" xyz="0 0 0"/>
    <inertial>
      <origin rpy="0 0 0" xyz="0 0 0"/>
      <mass value="1e-9"/>
      <inertia ixx="0" ixy="0" ixz="0" iyy="0" iyz="0" izz="0"/>
    </inertial>
  </link>
  <!-- Link moving_jaw_so101_v1 -->
  <link name="moving_jaw_so101_v1_link">
    <inertial>
      <origin rpy="0 0 0" xyz="-0.00157495 -0.0300244 0.0192755"/>
      <mass value="0.012"/>
      <inertia ixx="6.61427e-06" ixy="-3.19807e-07" ixz="-5.90717e-09" iyy="1.89032e-06" iyz="-1.09945e-07" izz="5.28738e-06"/>
    </inertial>
    <!-- Part moving_jaw_so101_v1 -->
    <visual>
      <origin rpy="9.53145e-17 6.93889e-18 1.24077e-24" xyz="-5.55112e-17 -5.55112e-17 0.0189"/>
      <geometry>
        <mesh filename="package://so101_description/meshes/so101/moving_jaw_so101_v1.stl"/>
      </geometry>
      <material name="3d_printed"/>
    </visual>
    <collision>
      <origin rpy="9.53145e-17 6.93889e-18 1.24077e-24" xyz="-5.55112e-17 -5.55112e-17 0.0189"/>
      <geometry>
        <mesh filename="package://so101_description/meshes/so101/moving_jaw_so101_v1.stl"/>
      </geometry>
    </collision>
  </link>
  <joint name="world_to_base" type="fixed">
    <parent link="world"/>
    <child link="base_link"/>
  </joint>
  <!-- fixed: gripper_link -> gripper_frame_link -->
  <joint name="gripper_frame_joint" type="fixed">
    <origin rpy="0 3.14159 0" xyz="-0.0079 -0.000218121 -0.0981274"/>
    <parent link="gripper_link"/>
    <child link="gripper_frame_link"/>
  </joint>
  <!-- gripper (gripper_link -> moving_jaw_so101_v1_link) -->
  <joint name="gripper" type="revolute">
    <origin rpy="1.5708 -5.24284e-08 -1.41553e-15" xyz="0.0202 0.0188 -0.0234"/>
    <parent link="gripper_link"/>
    <child link="moving_jaw_so101_v1_link"/>
    <axis xyz="0 0 1"/>
    <limit effort="10" lower="-0.174533" upper="1.74533" velocity="10"/>
  </joint>
  <!-- wrist_roll (wrist_link -> gripper_link) -->
  <joint name="wrist_roll" type="revolute">
    <origin rpy="1.5708 0.0486795 3.14159" xyz="5.55112e-17 -0.0611 0.0181"/>
    <parent link="wrist_link"/>
    <child link="gripper_link"/>
    <axis xyz="0 0 1"/>
    <limit effort="10" lower="-2.74385" upper="2.84121" velocity="10"/>
  </joint>
  <!-- wrist_flex (lower_arm_link -> wrist_link) -->
  <joint name="wrist_flex" type="revolute">
    <origin rpy="4.02456e-15 8.67362e-16 -1.5708" xyz="-0.1349 0.0052 3.62355e-17"/>
    <parent link="lower_arm_link"/>
    <child link="wrist_link"/>
    <axis xyz="0 0 1"/>
    <limit effort="10" lower="-1.65806" upper="1.65806" velocity="10"/>
  </joint>
  <!-- elbow_flex (upper_arm_link -> lower_arm_link) -->
  <!-- Note: 5-degree calibration offset reflected in limits -->
  <joint name="elbow_flex" type="revolute">
    <origin rpy="-3.63608e-16 8.74301e-16 1.5708" xyz="-0.11257 -0.028 1.73763e-16"/>
    <parent link="upper_arm_link"/>
    <child link="lower_arm_link"/>
    <axis xyz="0 0 1"/>
    <limit effort="10" lower="-1.69" upper="1.69" velocity="10"/>
  </joint>
  <!-- shoulder_lift (shoulder_link -> upper_arm_link) -->
  <joint name="shoulder_lift" type="revolute">
    <origin rpy="-1.5708 -1.5708 0" xyz="-0.0303992 -0.0182778 -0.0542"/>
    <parent link="shoulder_link"/>
    <child link="upper_arm_link"/>
    <axis xyz="0 0 1"/>
    <limit effort="10" lower="-1.74533" upper="1.74533" velocity="10"/>
  </joint>
  <!-- shoulder_pan (base_link -> shoulder_link) -->
  <joint name="shoulder_pan" type="revolute">
    <origin rpy="3.14159 4.18253e-17 -3.14159" xyz="0.0388353 -8.97657e-09 0.0624"/>
    <parent link="base_link"/>
    <child link="shoulder_link"/>
    <axis xyz="0 0 1"/>
    <limit effort="10" lower="-1.91986" upper="1.91986" velocity="10"/>
  </joint>
  <!-- For ROS 2 control (optional; add when you wire controllers) -->
  <!-- <xacro:include filename="$(find so101_description)/urdf/ros2_control.xacro"/> -->
</robot>
